<sdf version='1.6'>
  <model name='WAM-V'>
    <link name='wamv/base_link'>
      <pose frame=''>0 0 0 0 -0 0</pose>
      <inertial>
        <pose frame=''>0.001798 0.000246 0.127515 0 -0 0</pose>
        <mass>227.559</mass>
        <inertia>
          <ixx>182.426</ixx>
          <ixy>-0.040819</ixy>
          <ixz>-0.546839</ixz>
          <iyy>409.503</iyy>
          <iyz>-0.0746006</iyz>
          <izz>495.341</izz>
        </inertia>
      </inertial>
   
      <collision name='wamv/base_link_fixed_joint_lump__left_float_collision_4'>
        <pose frame=''>-0.4 1.03 0.2 3.14159 1.57079 3.14159</pose>
        <geometry>
          <cylinder>
            <length>4</length>
            <radius>0.2</radius>
          </cylinder>
        </geometry>
      </collision>
      <collision name='wamv/base_link_fixed_joint_lump__left_mid_float_collision_5'>
        <pose frame=''>1.85 1.03 0.3 0 1.38 0</pose>
        <geometry>
          <cylinder>
            <length>0.5</length>
            <radius>0.17</radius>
          </cylinder>
        </geometry>
      </collision>
      <collision name='wamv/base_link_fixed_joint_lump__left_front_float_collision_6'>
        <pose frame=''>2.3 1.03 0.4 0 1.3 0</pose>
        <geometry>
          <cylinder>
            <length>0.45</length>
            <radius>0.12</radius>
          </cylinder>
        </geometry>
      </collision>
      <collision name='wamv/base_link_fixed_joint_lump__front_left_beam_lower_collision_7'>
        <pose frame=''>0.9 0.85 1 0.78 -0 0</pose>
        <geometry>
          <cylinder>
            <length>0.5</length>
            <radius>0.04</radius>
          </cylinder>
        </geometry>
      </collision>
      <collision name='wamv/base_link_fixed_joint_lump__front_left_beam_upper_collision_8'>
        <pose frame=''>0.9 0.6 1.18 1.35 -0 0</pose>
        <geometry>
          <cylinder>
            <length>0.2</length>
            <radius>0.04</radius>
          </cylinder>
        </geometry>
      </collision>
      <collision name='wamv/base_link_fixed_joint_lump__mid_left_beam_lower_collision_9'>
        <pose frame=''>-0.65 0.99 0.7 0.1 0.25 0</pose>
        <geometry>
          <cylinder>
            <length>0.45</length>
            <radius>0.03</radius>
          </cylinder>
        </geometry>
      </collision>
      <collision name='wamv/base_link_fixed_joint_lump__mid_left_beam_medium_collision_10'>
        <pose frame=''>-0.57 0.87 1.05 0.75 0.25 0</pose>
        <geometry>
          <cylinder>
            <length>0.32</length>
            <radius>0.03</radius>
          </cylinder>
        </geometry>
      </collision>
      <collision name='wamv/base_link_fixed_joint_lump__mid_left_beam_upper_collision_11'>
        <pose frame=''>-0.55 0.65 1.17 1.35 0.25 0</pose>
        <geometry>
          <cylinder>
            <length>0.3</length>
            <radius>0.03</radius>
          </cylinder>
        </geometry>
      </collision>
      <collision name='wamv/base_link_fixed_joint_lump__rear_left_beam_lower_collision_12'>
        <pose frame=''>-0.74 1.03 0.7 0 -0.15 0</pose>
        <geometry>
          <cylinder>
            <length>0.45</length>
            <radius>0.03</radius>
          </cylinder>
        </geometry>
      </collision>
      <collision name='wamv/base_link_fixed_joint_lump__rear_left_beam_medium_collision_13'>
        <pose frame=''>-0.79 0.91 1.05 0.75 -0.15 -0</pose>
        <geometry>
          <cylinder>
            <length>0.32</length>
            <radius>0.03</radius>
          </cylinder>
        </geometry>
      </collision>
      <collision name='wamv/base_link_fixed_joint_lump__rear_left_beam_upper_collision_14'>
        <pose frame=''>-0.81 0.67 1.18 1.45 -0.15 0</pose>
        <geometry>
          <cylinder>
            <length>0.3</length>
            <radius>0.03</radius>
          </cylinder>
        </geometry>
      </collision>
      <collision name='wamv/base_link_fixed_joint_lump__left_joint_collision_15'>
        <pose frame=''>0.58 1.03 0.6 0 -0.6 0</pose>
        <geometry>
          <box>
            <size>0.65 0.2 0.1</size>
          </box>
        </geometry>
      </collision>
      <collision name='wamv/base_link_fixed_joint_lump__right_float_collision_16'>
        <pose frame=''>-0.4 -1.03 0.2 3.14159 1.57079 3.14159</pose>
        <geometry>
          <cylinder>
            <length>4</length>
            <radius>0.2</radius>
          </cylinder>
        </geometry>
      </collision>
      <collision name='wamv/base_link_fixed_joint_lump__right_mid_float_collision_17'>
        <pose frame=''>1.85 -1.03 0.3 0 1.38 0</pose>
        <geometry>
          <cylinder>
            <length>0.5</length>
            <radius>0.17</radius>
          </cylinder>
        </geometry>
      </collision>
      <collision name='wamv/base_link_fixed_joint_lump__right_front_float_collision_18'>
        <pose frame=''>2.3 -1.03 0.4 0 1.3 0</pose>
        <geometry>
          <cylinder>
            <length>0.45</length>
            <radius>0.12</radius>
          </cylinder>
        </geometry>
      </collision>
      <collision name='wamv/base_link_fixed_joint_lump__front_right_beam_lower_collision_19'>
        <pose frame=''>0.9 -0.85 1 -0.78 0 0</pose>
        <geometry>
          <cylinder>
            <length>0.5</length>
            <radius>0.04</radius>
          </cylinder>
        </geometry>
      </collision>
      <collision name='wamv/base_link_fixed_joint_lump__front_right_beam_upper_collision_20'>
        <pose frame=''>0.9 -0.6 1.18 -1.35 0 0</pose>
        <geometry>
          <cylinder>
            <length>0.2</length>
            <radius>0.04</radius>
          </cylinder>
        </geometry>
      </collision>
      <collision name='wamv/base_link_fixed_joint_lump__mid_right_beam_lower_collision_21'>
        <pose frame=''>-0.65 -0.99 0.7 -0.1 0.25 0</pose>
        <geometry>
          <cylinder>
            <length>0.45</length>
            <radius>0.03</radius>
          </cylinder>
        </geometry>
      </collision>
      <collision name='wamv/base_link_fixed_joint_lump__mid_right_beam_medium_collision_22'>
        <pose frame=''>-0.57 -0.87 1.05 -0.75 0.25 0</pose>
        <geometry>
          <cylinder>
            <length>0.32</length>
            <radius>0.03</radius>
          </cylinder>
        </geometry>
      </collision>
      <collision name='wamv/base_link_fixed_joint_lump__mid_right_beam_upper_collision_23'>
        <pose frame=''>-0.55 -0.65 1.17 -1.35 0.25 0</pose>
        <geometry>
          <cylinder>
            <length>0.3</length>
            <radius>0.03</radius>
          </cylinder>
        </geometry>
      </collision>
      <collision name='wamv/base_link_fixed_joint_lump__rear_right_beam_lower_collision_24'>
        <pose frame=''>-0.74 -1.03 0.7 0 -0.15 0</pose>
        <geometry>
          <cylinder>
            <length>0.45</length>
            <radius>0.03</radius>
          </cylinder>
        </geometry>
      </collision>
      <collision name='wamv/base_link_fixed_joint_lump__rear_right_beam_medium_collision_25'>
        <pose frame=''>-0.79 -0.91 1.05 -0.75 -0.15 0</pose>
        <geometry>
          <cylinder>
            <length>0.32</length>
            <radius>0.03</radius>
          </cylinder>
        </geometry>
      </collision>
      <collision name='wamv/base_link_fixed_joint_lump__rear_right_beam_upper_collision_26'>
        <pose frame=''>-0.81 -0.67 1.18 -1.45 -0.15 0</pose>
        <geometry>
          <cylinder>
            <length>0.3</length>
            <radius>0.03</radius>
          </cylinder>
        </geometry>
      </collision>
      <collision name='wamv/base_link_fixed_joint_lump__right_joint_collision_27'>
        <pose frame=''>0.58 -1.03 0.6 0 -0.6 0</pose>
        <geometry>
          <box>
            <size>0.65 0.2 0.1</size>
          </box>
        </geometry>
      </collision>
      <collision name='wamv/base_link_fixed_joint_lump__top_base_collision_28'>
        <pose frame=''>0 0 1.25 0 -0 0</pose>
        <geometry>
          <box>
            <size>1.85 1 0.1</size>
          </box>
        </geometry>
      </collision>
      <collision name='wamv/base_link_fixed_joint_lump__left_battery_collision_collision_29'>
        <pose frame=''>0 1 0.6 0 -0 0</pose>
        <geometry>
          <box>
            <size>0.6 0.4 0.31</size>
          </box>
        </geometry>
      </collision>
      <collision name='wamv/base_link_fixed_joint_lump__right_battery_collision_collision_30'>
        <pose frame=''>0 -1 0.6 0 -0 0</pose>
        <geometry>
          <box>
            <size>0.6 0.4 0.31</size>
          </box>
        </geometry>
      </collision>
      <visual name='wamv/base_link_fixed_joint_lump__wamv/up_camera_post_link_visual'>
        <pose frame=''>0.7 0.1 1.38475 0 -0 0</pose>
        <geometry>
          <cylinder>
            <length>0.1765</length>
            <radius>0.0076</radius>
          </cylinder>
        </geometry>
        <material>
          <script>
            <name>Gazebo/Black</name>
            <uri>file://media/materials/scripts/gazebo.material</uri>
          </script>
        </material>
      </visual>
      <visual name='wamv/base_link_fixed_joint_lump__up_camera_post_arm_visual_visual_1'>
        <pose frame=''>0.692 0.1 1.47 -1.0472 -0 -1.5708</pose>
        <geometry>
          <mesh>
            <scale>1 1 1</scale>
            <uri>model://vrx_gazebo/models/sensor_post/mesh/sensor_post_arm.dae</uri>
          </mesh>
        </geometry>
      </visual>
      <visual name='wamv/base_link_fixed_joint_lump__up_camera_visual_visual_2'>
        <pose frame=''>0.75 0.1 1.467 -1.5708 -0 1.5708</pose>
        <geometry>
          <mesh>
            <scale>1 1 1</scale>
            <uri>model://vrx_gazebo/models/mono_camera/mesh/mono_camera.dae</uri>
          </mesh>
        </geometry>
      </visual>
      <visual name='wamv/base_link_fixed_joint_lump__wamv/dummy_link_visual_3'>
        <pose frame=''>0 0 0 0 -0 0</pose>
        <geometry>
          <mesh>
            <scale>1 1 1</scale>
            <uri>model://wamv_description/models/WAM-V-Base/mesh/WAM-V-Base.dae</uri>
          </mesh>
        </geometry>
      </visual>
      <visual name='wamv/base_link_fixed_joint_lump__wamv/qr_code_visual_4'>
        <pose frame=''>0 0 1.3 0 -0 0</pose>
        <geometry>
          <box>
            <size>0.6 0.6 0.01</size>
          </box>
        </geometry>
      </visual>
      <visual name='wamv/base_link_fixed_joint_lump__left_battery_visual_visual_5'>
        <pose frame=''>0 -0.03 0 0 -0 0</pose>
        <geometry>
          <mesh>
            <scale>1 1 1</scale>
            <uri>model://vrx_gazebo/models/battery/mesh/battery.dae</uri>
          </mesh>
        </geometry>
      </visual>
      <visual name='wamv/base_link_fixed_joint_lump__right_battery_visual_visual_6'>
        <pose frame=''>0 -2.03 0 0 -0 0</pose>
        <geometry>
          <mesh>
            <scale>1 1 1</scale>
            <uri>model://vrx_gazebo/models/battery/mesh/battery.dae</uri>
          </mesh>
        </geometry>
      </visual>
      <velocity_decay/>
      <gravity>1</gravity>
      <velocity_decay/>
     
    </link>
    <link name='wamv/left_engine_link'>
      <pose frame=''>-2.37378 1.02713 0.318237 0 -0 0</pose>
      <inertial>
        <pose frame=''>0 0 0 0 -0 0</pose>
        <mass>15</mass>
        <inertia>
          <ixx>0.889245</ixx>
          <ixy>0</ixy>
          <ixz>0</ixz>
          <iyy>0.911125</iyy>
          <iyz>0</iyz>
          <izz>0.078125</izz>
        </inertia>
      </inertial>
      <collision name='wamv/left_engine_link_fixed_joint_lump__left_engine_vertical_axis_collision_collision'>
        <pose frame=''>-0.16 0 -0.24 0 -0 0</pose>
        <geometry>
          <box>
            <size>0.2 0.15 0.83</size>
          </box>
        </geometry>
      </collision>
      <collision name='wamv/left_engine_link_fixed_joint_lump__left_engine_rear_end_collision_collision_1'>
        <pose frame=''>-0.34 0 0.12 0 -0 0</pose>
        <geometry>
          <box>
            <size>0.12 0.15 0.12</size>
          </box>
        </geometry>
      </collision>
      <visual name='wamv/left_engine_link_visual'>
        <pose frame=''>0 0 0 0 -0 0</pose>
        <geometry>
          <mesh>
            <scale>1 1 1</scale>
            <uri>model://wamv_description/models/engine/mesh/engine.dae</uri>
          </mesh>
        </geometry>
      </visual>
    </link>
    <joint name='wamv/left_chasis_engine_joint' type='revolute'>
      <child>wamv/left_engine_link</child>
      <parent>wamv/base_link</parent>
      <axis>
        <xyz>0 0 1</xyz>
        <limit>
          <lower>-3.14159</lower>
          <upper>3.14159</upper>
          <effort>10</effort>
          <velocity>10</velocity>
        </limit>
        <dynamics>
          <spring_reference>0</spring_reference>
          <spring_stiffness>0</spring_stiffness>
        </dynamics>
        <use_parent_model_frame>0</use_parent_model_frame>
      </axis>
    </joint>
    <link name='wamv/left_propeller_link'>
      <pose frame=''>-2.65193 1.02713 -0.191134 0 -0 0</pose>
      <inertial>
        <pose frame=''>0 0 0 0 -0 0</pose>
        <mass>0.5</mass>
        <inertia>
          <ixx>0.008545</ixx>
          <ixy>0</ixy>
          <ixz>0</ixz>
          <iyy>0.008545</iyy>
          <iyz>0</iyz>
          <izz>0.0144</izz>
        </inertia>
      </inertial>
      <collision name='wamv/left_propeller_link_fixed_joint_lump__left_propeller_collision_collision'>
        <pose frame=''>-0.08 0 0 3.14159 1.57079 3.14159</pose>
        <geometry>
          <cylinder>
            <length>0.18</length>
            <radius>0.24</radius>
          </cylinder>
        </geometry>
      </collision>
      <visual name='wamv/left_propeller_link_visual'>
        <pose frame=''>0 0 0 0 -0 0</pose>
        <geometry>
          <mesh>
            <scale>1 1 1</scale>
            <uri>model://wamv_description/models/propeller/mesh/propeller.dae</uri>
          </mesh>
        </geometry>
      </visual>
    </link>
    <joint name='wamv/left_engine_propeller_joint' type='revolute'>
      <child>wamv/left_propeller_link</child>
      <parent>wamv/left_engine_link</parent>
      <axis>
        <xyz>1 0 0</xyz>
        <limit>
          <lower>-1e+16</lower>
          <upper>1e+16</upper>
        </limit>
        <dynamics>
          <damping>0.05</damping>
          <friction>0.05</friction>
          <spring_reference>0</spring_reference>
          <spring_stiffness>0</spring_stiffness>
        </dynamics>
        <use_parent_model_frame>0</use_parent_model_frame>
      </axis>
    </joint>
    <link name='wamv/right_engine_link'>
      <pose frame=''>-2.37378 -1.02713 0.318237 0 -0 0</pose>
      <inertial>
        <pose frame=''>0 0 0 0 -0 0</pose>
        <mass>15</mass>
        <inertia>
          <ixx>0.889245</ixx>
          <ixy>0</ixy>
          <ixz>0</ixz>
          <iyy>0.911125</iyy>
          <iyz>0</iyz>
          <izz>0.078125</izz>
        </inertia>
      </inertial>
      <collision name='wamv/right_engine_link_fixed_joint_lump__right_engine_vertical_axis_collision_collision'>
        <pose frame=''>-0.16 0 -0.24 0 -0 0</pose>
        <geometry>
          <box>
            <size>0.2 0.15 0.83</size>
          </box>
        </geometry>
      </collision>
      <collision name='wamv/right_engine_link_fixed_joint_lump__right_engine_rear_end_collision_collision_1'>
        <pose frame=''>-0.34 0 0.12 0 -0 0</pose>
        <geometry>
          <box>
            <size>0.12 0.15 0.12</size>
          </box>
        </geometry>
      </collision>
      <visual name='wamv/right_engine_link_visual'>
        <pose frame=''>0 0 0 0 -0 0</pose>
        <geometry>
          <mesh>
            <scale>1 1 1</scale>
            <uri>model://wamv_description/models/engine/mesh/engine.dae</uri>
          </mesh>
        </geometry>
      </visual>
    </link>
    <joint name='wamv/right_chasis_engine_joint' type='revolute'>
      <child>wamv/right_engine_link</child>
      <parent>wamv/base_link</parent>
      <axis>
        <xyz>0 0 1</xyz>
        <limit>
          <lower>-3.14159</lower>
          <upper>3.14159</upper>
          <effort>10</effort>
          <velocity>10</velocity>
        </limit>
        <dynamics>
          <spring_reference>0</spring_reference>
          <spring_stiffness>0</spring_stiffness>
        </dynamics>
        <use_parent_model_frame>0</use_parent_model_frame>
      </axis>
    </joint>
    <link name='wamv/right_propeller_link'>
      <pose frame=''>-2.65193 -1.02713 -0.191134 0 -0 0</pose>
      <inertial>
        <pose frame=''>0 0 0 0 -0 0</pose>
        <mass>0.5</mass>
        <inertia>
          <ixx>0.008545</ixx>
          <ixy>0</ixy>
          <ixz>0</ixz>
          <iyy>0.008545</iyy>
          <iyz>0</iyz>
          <izz>0.0144</izz>
        </inertia>
      </inertial>
      <collision name='wamv/right_propeller_link_fixed_joint_lump__right_propeller_collision_collision'>
        <pose frame=''>-0.08 0 0 3.14159 1.57079 3.14159</pose>
        <geometry>
          <cylinder>
            <length>0.18</length>
            <radius>0.24</radius>
          </cylinder>
        </geometry>
      </collision>
      <visual name='wamv/right_propeller_link_visual'>
        <pose frame=''>0 0 0 0 -0 0</pose>
        <geometry>
          <mesh>
            <scale>1 1 1</scale>
            <uri>model://wamv_description/models/propeller/mesh/propeller.dae</uri>
          </mesh>
        </geometry>
      </visual>
    </link>
    <joint name='wamv/right_engine_propeller_joint' type='revolute'>
      <child>wamv/right_propeller_link</child>
      <parent>wamv/right_engine_link</parent>
      <axis>
        <xyz>1 0 0</xyz>
        <limit>
          <lower>-1e+16</lower>
          <upper>1e+16</upper>
        </limit>
        <dynamics>
          <damping>0.05</damping>
          <friction>0.05</friction>
          <spring_reference>0</spring_reference>
          <spring_stiffness>0</spring_stiffness>
        </dynamics>
        <use_parent_model_frame>0</use_parent_model_frame>
      </axis>
    </joint>
    <plugin name='wamv_gazebo_thrust' filename='libusv_gazebo_thrust_plugin.so'>
      <cmdTimeout>1.0</cmdTimeout>
      <publisherRate>100.0</publisherRate>
      <robotNamespace>wamv</robotNamespace>
      <thruster>
        <linkName>wamv/left_propeller_link</linkName>
        <propJointName>wamv/left_engine_propeller_joint</propJointName>
        <engineJointName>wamv/left_chasis_engine_joint</engineJointName>
        <cmdTopic>thrusters/left_thrust_cmd</cmdTopic>
        <angleTopic>thrusters/left_thrust_angle</angleTopic>
        <enableAngle>1</enableAngle>
        <mappingType>1</mappingType>
        <maxCmd>1.0</maxCmd>
        <maxForceFwd>250.0</maxForceFwd>
        <maxForceRev>-100.0</maxForceRev>
        <maxAngle>1.57079632679</maxAngle>
      </thruster>
      <thruster>
        <linkName>wamv/right_propeller_link</linkName>
        <propJointName>wamv/right_engine_propeller_joint</propJointName>
        <engineJointName>wamv/right_chasis_engine_joint</engineJointName>
        <cmdTopic>thrusters/right_thrust_cmd</cmdTopic>
        <angleTopic>thrusters/right_thrust_angle</angleTopic>
        <enableAngle>1</enableAngle>
        <mappingType>1</mappingType>
        <maxCmd>1.0</maxCmd>
        <maxForceFwd>250.0</maxForceFwd>
        <maxForceRev>-100.0</maxForceRev>
        <maxAngle>1.57079632679</maxAngle>
      </thruster>
    </plugin>
    <static>0</static>
    <plugin name='usv_dynamics_wamv_dynamics_plugin' filename='libusv_gazebo_dynamics_plugin.so'>
      <bodyName>wamv/base_link</bodyName>
      <waterLevel>0</waterLevel>
      <waterDensity>997.8</waterDensity>
      <xDotU>0.0</xDotU>
      <yDotV>0.0</yDotV>
      <nDotR>0.0</nDotR>
      <xU>51.3</xU>
      <xUU>72.4</xUU>
      <yV>40.0</yV>
      <yVV>0.0</yVV>
      <zW>500.0</zW>
      <kP>50.0</kP>
      <mQ>50.0</mQ>
      <nR>400.0</nR>
      <nRR>0.0</nRR>
      <hullRadius>0.213</hullRadius>
      <boatWidth>2.4</boatWidth>
      <boatLength>4.9</boatLength>
      <length_n>2</length_n>
      <wave_model>ocean_waves</wave_model>
    </plugin>
  </model>
</sdf>
