<sdf version='1.6'>
  <model name='mrobot'>
    <link name='base_footprint'>
      <pose frame=''>0 0 0 0 -0 0</pose>
      <inertial>
        <pose frame=''>0.013545 0 0.078721 0 -0 0</pose>
        <mass>0.818</mass>
        <inertia>
          <ixx>0.0171712</ixx>
          <ixy>7.34289e-22</ixy>
          <ixz>-0.00106581</ixz>
          <iyy>0.0181523</iyy>
          <iyz>2.47856e-21</iyz>
          <izz>0.0178163</izz>
        </inertia>
      </inertial>
      <collision name='base_footprint_fixed_joint_lump__base_link_collision'>
        <pose frame=''>0 0 0.033 0 -0 0</pose>
        <geometry>
          <cylinder>
            <length>0.005</length>
            <radius>0.13</radius>
          </cylinder>
        </geometry>
        <surface>
          <contact>
            <ode/>
          </contact>
          <friction>
            <ode/>
          </friction>
        </surface>
      </collision>
      <collision name='base_footprint_fixed_joint_lump__front_caster_link_collision_1'>
        <pose frame=''>0.12 0 0.017 0 -0 0</pose>
        <geometry>
          <sphere>
            <radius>0.016</radius>
          </sphere>
        </geometry>
        <surface>
          <contact>
            <ode/>
          </contact>
          <friction>
            <ode/>
          </friction>
        </surface>
      </collision>
      <collision name='base_footprint_fixed_joint_lump__plate_1_link_collision_2'>
        <pose frame=''>0 0 0.103 0 -0 0</pose>
        <geometry>
          <cylinder>
            <length>0.005</length>
            <radius>0.13</radius>
          </cylinder>
        </geometry>
        <surface>
          <contact>
            <ode/>
          </contact>
          <friction>
            <ode/>
          </friction>
        </surface>
      </collision>
      <collision name='base_footprint_fixed_joint_lump__plate_2_link_collision_3'>
        <pose frame=''>0 0 0.173 0 -0 0</pose>
        <geometry>
          <box>
            <size>0.6 0.6 .01</size>
          </box>
        </geometry>
        <surface>
          <contact>
            <ode/>
          </contact>
          <friction>
            <ode/>
          </friction>
        </surface>
      </collision>
      <collision name='base_footprint_fixed_joint_lump__camera_link_collision_4'>
        <pose frame=''>0.1 0 0.193 0 -0 0</pose>
        <geometry>
          <box>
            <size>0.01 0.04 0.04</size>
          </box>
        </geometry>
        <surface>
          <contact>
            <ode/>
          </contact>
          <friction>
            <ode/>
          </friction>
        </surface>
      </collision>
      <collision name='base_footprint_fixed_joint_lump__standoff_2in_1_link_collision_5'>
        <pose frame=''>-0.09 -0.07 0.068 0 -0 0</pose>
        <geometry>
          <box>
            <size>0.01 0.01 0.07</size>
          </box>
        </geometry>
      </collision>
      <collision name='base_footprint_fixed_joint_lump__standoff_2in_5_link_collision_6'>
        <pose frame=''>-0.09 -0.07 0.138 0 -0 0</pose>
        <geometry>
          <box>
            <size>0.01 0.01 0.07</size>
          </box>
        </geometry>
      </collision>
      <collision name='base_footprint_fixed_joint_lump__standoff_2in_2_link_collision_7'>
        <pose frame=''>-0.09 0.07 0.068 0 -0 0</pose>
        <geometry>
          <box>
            <size>0.01 0.01 0.07</size>
          </box>
        </geometry>
      </collision>
      <collision name='base_footprint_fixed_joint_lump__standoff_2in_6_link_collision_8'>
        <pose frame=''>-0.09 0.07 0.138 0 -0 0</pose>
        <geometry>
          <box>
            <size>0.01 0.01 0.07</size>
          </box>
        </geometry>
      </collision>
      <collision name='base_footprint_fixed_joint_lump__standoff_2in_3_link_collision_9'>
        <pose frame=''>0.06 -0.1 0.068 0 -0 0</pose>
        <geometry>
          <box>
            <size>0.01 0.01 0.07</size>
          </box>
        </geometry>
      </collision>
      <collision name='base_footprint_fixed_joint_lump__standoff_2in_7_link_collision_10'>
        <pose frame=''>0.06 -0.1 0.138 0 -0 0</pose>
        <geometry>
          <box>
            <size>0.01 0.01 0.07</size>
          </box>
        </geometry>
      </collision>
      <collision name='base_footprint_fixed_joint_lump__standoff_2in_4_link_collision_11'>
        <pose frame=''>0.06 0.1 0.068 0 -0 0</pose>
        <geometry>
          <box>
            <size>0.01 0.01 0.07</size>
          </box>
        </geometry>
      </collision>
      <collision name='base_footprint_fixed_joint_lump__standoff_2in_8_link_collision_12'>
        <pose frame=''>0.06 0.1 0.138 0 -0 0</pose>
        <geometry>
          <box>
            <size>0.01 0.01 0.07</size>
          </box>
        </geometry>
      </collision>
      <visual name='base_footprint_visual'>
        <pose frame=''>0 0 0 0 -0 0</pose>
        <geometry>
          <box>
            <size>0.001 0.001 0.001</size>
          </box>
        </geometry>
      </visual>
      <visual name='base_footprint_fixed_joint_lump__base_link_visual_1'>
        <pose frame=''>0 0 0.033 0 -0 0</pose>
        <geometry>
          <cylinder>
            <length>0.005</length>
            <radius>0.13</radius>
          </cylinder>
        </geometry>
        <material>
          <script>
            <name>Gazebo/Blue</name>
            <uri>file://media/materials/scripts/gazebo.material</uri>
          </script>
        </material>
      </visual>
      <visual name='base_footprint_fixed_joint_lump__front_caster_link_visual_2'>
        <pose frame=''>0.12 0 0.017 0 -0 0</pose>
        <geometry>
          <sphere>
            <radius>0.016</radius>
          </sphere>
        </geometry>
        <material>
          <script>
            <name>Gazebo/Black</name>
            <uri>file://media/materials/scripts/gazebo.material</uri>
          </script>
        </material>
      </visual>
      <visual name='base_footprint_fixed_joint_lump__plate_1_link_visual_3'>
        <pose frame=''>0 0 0.103 0 -0 0</pose>
        <geometry>
          <cylinder>
            <length>0.005</length>
            <radius>0.13</radius>
          </cylinder>
        </geometry>
        <material>
          <script>
            <name>Gazebo/Blue</name>
            <uri>file://media/materials/scripts/gazebo.material</uri>
          </script>
        </material>
      </visual>
      <visual name='base_footprint_fixed_joint_lump__plate_2_link_visual_4'>
        <pose frame=''>0 0 0.173 0 -0 0</pose>
        <geometry>
          <box>
            <size>0.6 0.6 .01</size>
          </box>
        </geometry>
        <material>
          <script>
            <uri>model://my_landing_pad/materials/scripts</uri>
	          <uri>model://my_landing_pad/materials/textures</uri>
            <name>Cube/my_landing_pad</name>
          </script>
        </material>
      </visual>
      <visual name='base_footprint_fixed_joint_lump__camera_link_visual_5'>
        <pose frame=''>0.1 0 0.18 0 -0 0</pose>
        <geometry>
          <box>
            <size>0.01 0.04 0.01</size>
          </box>
        </geometry>
        <material>
          <script>
            <name>Gazebo/Black</name>
            <uri>file://media/materials/scripts/gazebo.material</uri>
          </script>
        </material>
      </visual>
      <visual name='base_footprint_fixed_joint_lump__standoff_2in_1_link_visual_6'>
        <pose frame=''>-0.09 -0.07 0.068 0 -0 0</pose>
        <geometry>
          <box>
            <size>0.01 0.01 0.07</size>
          </box>
        </geometry>
      </visual>
      <visual name='base_footprint_fixed_joint_lump__standoff_2in_5_link_visual_7'>
        <pose frame=''>-0.09 -0.07 0.138 0 -0 0</pose>
        <geometry>
          <box>
            <size>0.01 0.01 0.07</size>
          </box>
        </geometry>
      </visual>
      <visual name='base_footprint_fixed_joint_lump__standoff_2in_2_link_visual_8'>
        <pose frame=''>-0.09 0.07 0.068 0 -0 0</pose>
        <geometry>
          <box>
            <size>0.01 0.01 0.07</size>
          </box>
        </geometry>
      </visual>
      <visual name='base_footprint_fixed_joint_lump__standoff_2in_6_link_visual_9'>
        <pose frame=''>-0.09 0.07 0.138 0 -0 0</pose>
        <geometry>
          <box>
            <size>0.01 0.01 0.07</size>
          </box>
        </geometry>
      </visual>
      <visual name='base_footprint_fixed_joint_lump__standoff_2in_3_link_visual_10'>
        <pose frame=''>0.06 -0.1 0.068 0 -0 0</pose>
        <geometry>
          <box>
            <size>0.01 0.01 0.07</size>
          </box>
        </geometry>
      </visual>
      <visual name='base_footprint_fixed_joint_lump__standoff_2in_7_link_visual_11'>
        <pose frame=''>0.06 -0.1 0.138 0 -0 0</pose>
        <geometry>
          <box>
            <size>0.01 0.01 0.07</size>
          </box>
        </geometry>
      </visual>
      <visual name='base_footprint_fixed_joint_lump__standoff_2in_4_link_visual_12'>
        <pose frame=''>0.06 0.1 0.068 0 -0 0</pose>
        <geometry>
          <box>
            <size>0.01 0.01 0.07</size>
          </box>
        </geometry>
      </visual>
      <visual name='base_footprint_fixed_joint_lump__standoff_2in_8_link_visual_13'>
        <pose frame=''>0.06 0.1 0.138 0 -0 0</pose>
        <geometry>
          <box>
            <size>0.01 0.01 0.07</size>
          </box>
        </geometry>
      </visual>
      <velocity_decay/>
      <velocity_decay/>
      <velocity_decay/>
      <velocity_decay/>
      <velocity_decay/>
      <gravity>1</gravity>
      <velocity_decay/>
      
      <sensor name='camera_on_car' type='camera'>
        <update_rate>30</update_rate>
        <camera name='head'>
          <pose frame=''>0 0 0 0 -1.57 0</pose>
          <horizontal_fov>1.39626</horizontal_fov>
          <image>
            <width>1280</width>
            <height>720</height>
            <format>R8G8B8</format>
          </image>
          <clip>
            <near>0.02</near>
            <far>300</far>
          </clip>
          <noise>
            <type>gaussian</type>
            <mean>0</mean>
            <stddev>0.007</stddev>
          </noise>
        </camera>
        <plugin name='gazebo_camera' filename='libgazebo_ros_camera.so'>
          <alwaysOn>1</alwaysOn>
          <updateRate>0.0</updateRate>
          <cameraName>/camera_on_car</cameraName>
          <imageTopicName>image_raw_from_car</imageTopicName>
          <cameraInfoTopicName>camera_info_on_car</cameraInfoTopicName>
          <frameName>camera_link</frameName>
          <hackBaseline>0.07</hackBaseline>
          <distortionK1>0.0</distortionK1>
          <distortionK2>0.0</distortionK2>
          <distortionK3>0.0</distortionK3>
          <distortionT1>0.0</distortionT1>
          <distortionT2>0.0</distortionT2>
        </plugin>
        <pose frame=''>0.1 0 0.193 0 -0 0</pose>
      </sensor>
    </link>
    <link name='wheel_left_link'>
      <pose frame=''>-0.05 -0.13 0.033 0 -0 0</pose>
      <inertial>
        <pose frame=''>0 0 0 0 -0 0</pose>
        <mass>0.1</mass>
        <inertia>
          <ixx>2.96333e-05</ixx>
          <ixy>0</ixy>
          <ixz>0</ixz>
          <iyy>2.96333e-05</iyy>
          <iyz>0</iyz>
          <izz>5.445e-05</izz>
        </inertia>
      </inertial>
      <collision name='wheel_left_link_collision'>
        <pose frame=''>0 0 0 1.5708 -0 0</pose>
        <geometry>
          <cylinder>
            <length>0.017</length>
            <radius>0.033</radius>
          </cylinder>
        </geometry>
        <surface>
          <contact>
            <ode/>
          </contact>
          <friction>
            <ode/>
          </friction>
        </surface>
      </collision>
      <visual name='wheel_left_link_visual'>
        <pose frame=''>0 0 0 1.5708 -0 0</pose>
        <geometry>
          <cylinder>
            <length>0.017</length>
            <radius>0.033</radius>
          </cylinder>
        </geometry>
        <material>
          <script>
            <name>Gazebo/Black</name>
            <uri>file://media/materials/scripts/gazebo.material</uri>
          </script>
        </material>
      </visual>
      <gravity>1</gravity>
      <velocity_decay/>
    </link>
    <joint name='base_to_wheel_left_joint' type='revolute'>
      <child>wheel_left_link</child>
      <parent>base_footprint</parent>
      <axis>
        <xyz>1 0 0</xyz>
        <limit>
          <lower>-1e+16</lower>
          <upper>1e+16</upper>
        </limit>
        <dynamics>
          <spring_reference>0</spring_reference>
          <spring_stiffness>0</spring_stiffness>
        </dynamics>
        <use_parent_model_frame>0</use_parent_model_frame>
      </axis>
    </joint>
    <link name='wheel_right_link'>
      <pose frame=''>-0.05 0.13 0.033 0 -0 0</pose>
      <inertial>
        <pose frame=''>0 0 0 0 -0 0</pose>
        <mass>0.1</mass>
        <inertia>
          <ixx>2.96333e-05</ixx>
          <ixy>0</ixy>
          <ixz>0</ixz>
          <iyy>2.96333e-05</iyy>
          <iyz>0</iyz>
          <izz>5.445e-05</izz>
        </inertia>
      </inertial>
      <collision name='wheel_right_link_collision'>
        <pose frame=''>0 0 0 1.5708 -0 0</pose>
        <geometry>
          <cylinder>
            <length>0.017</length>
            <radius>0.033</radius>
          </cylinder>
        </geometry>
        <surface>
          <contact>
            <ode/>
          </contact>
          <friction>
            <ode/>
          </friction>
        </surface>
      </collision>
      <visual name='wheel_right_link_visual'>
        <pose frame=''>0 0 0 1.5708 -0 0</pose>
        <geometry>
          <cylinder>
            <length>0.017</length>
            <radius>0.033</radius>
          </cylinder>
        </geometry>
        <material>
          <script>
            <name>Gazebo/Black</name>
            <uri>file://media/materials/scripts/gazebo.material</uri>
          </script>
        </material>
      </visual>
      <gravity>1</gravity>
      <velocity_decay/>
    </link>
    <joint name='base_to_wheel_right_joint' type='revolute'>
      <child>wheel_right_link</child>
      <parent>base_footprint</parent>
      <axis>
        <xyz>1 0 0</xyz>
        <limit>
          <lower>-1e+16</lower>
          <upper>1e+16</upper>
        </limit>
        <dynamics>
          <spring_reference>0</spring_reference>
          <spring_stiffness>0</spring_stiffness>
        </dynamics>
        <use_parent_model_frame>0</use_parent_model_frame>
      </axis>
    </joint>
    <static>0</static>
    <plugin name='differential_drive_controller' filename='libgazebo_ros_diff_drive.so'>
      <rosDebugLevel>Debug</rosDebugLevel>
      <publishWheelTF>1</publishWheelTF>
      <robotNamespace>/</robotNamespace>
      <publishTf>1</publishTf>
      <publishWheelJointState>1</publishWheelJointState>
      <alwaysOn>1</alwaysOn>
      <updateRate>100.0</updateRate>
      <legacyMode>1</legacyMode>
      <leftJoint>base_to_wheel_left_joint</leftJoint>
      <rightJoint>base_to_wheel_right_joint</rightJoint>
      <wheelSeparation>0.26</wheelSeparation>
      <wheelDiameter>0.066</wheelDiameter>
      <broadcastTF>1</broadcastTF>
      <wheelTorque>30</wheelTorque>
      <wheelAcceleration>1.8</wheelAcceleration>
      <commandTopic>cmd_vel</commandTopic>
      <odometryFrame>odom</odometryFrame>
      <odometryTopic>odom</odometryTopic>
      <robotBaseFrame>base_footprint</robotBaseFrame>
    </plugin>
  </model>
</sdf>
