<sdf version='1.6'>
  <model name='wind_motor'>
    <link name='base'>
      <pose frame=''>0 0 0 0 -0 0</pose>
      <inertial>
        <pose frame=''>-0 0 2.13203 0 -0 0</pose>
        <mass>239.677</mass>
        <inertia>
          <ixx>474.449</ixx>
          <ixy>1.66614e-31</ixy>
          <ixz>2.7846e-15</ixz>
          <iyy>474.449</iyy>
          <iyz>-2.89314e-14</iyz>
          <izz>1.94778</izz>
        </inertia>
      </inertial>
      <collision name='base_collision'>
        <pose frame=''>0 0 0 0 -0 0</pose>
        <geometry>
          <mesh>
            <scale>1 1 1</scale>
            <uri>model://wind_motor/meshes/base.STL</uri>
          </mesh>
        </geometry>
      </collision>
      <visual name='base_visual'>
        <pose frame=''>0 0 0 0 -0 0</pose>
        <geometry>
          <mesh>
            <scale>1 1 1</scale>
            <uri>model://wind_motor/meshes/base.STL</uri>
          </mesh>
        </geometry>
      </visual>
    </link>
    <joint name='fixed' type='fixed'>
      <child>base</child>
      <parent>world</parent>
    </joint>
    <link name='motor'>
      <pose frame=''>0 0 5 -2.96669 -1.57079 3.14159</pose>
      <inertial>
        <pose frame=''>0.299421 -0.005999 0.04614 0 -0 0</pose>
        <mass>99.867</mass>
        <inertia>
          <ixx>4.18133</ixx>
          <ixy>0.00979875</ixy>
          <ixz>-0.0753931</ixz>
          <iyy>4.2567</iyy>
          <iyz>0.233542</iyz>
          <izz>2.49069</izz>
        </inertia>
      </inertial>
      <collision name='motor_collision'>
        <pose frame=''>0 0 0 0 -0 0</pose>
        <geometry>
          <mesh>
            <scale>1 1 1</scale>
            <uri>model://wind_motor/meshes/motor.STL</uri>
          </mesh>
        </geometry>
      </collision>
      <visual name='motor_visual'>
        <pose frame=''>0 0 0 0 -0 0</pose>
        <geometry>
          <mesh>
            <scale>1 1 1</scale>
            <uri>model://wind_motor/meshes/motor.STL</uri>
          </mesh>
        </geometry>
      </visual>
    </link>
    <joint name='base_motor_joint' type='revolute'>
      <child>motor</child>
      <parent>base</parent>
      <axis>
        <xyz>1 0 0</xyz>
        <limit>
          <lower>-1e+16</lower>
          <upper>1e+16</upper>
        </limit>
        <dynamics>
          <spring_reference>0</spring_reference>
          <spring_stiffness>0</spring_stiffness>
        </dynamics>
        <use_parent_model_frame>0</use_parent_model_frame>
      </axis>
    </joint>
    <link name='blade'>
      <pose frame=''>-1e-06 0 5.3048 -1.5708 -1.06719 1.7457</pose>
      <inertial>
        <pose frame=''>0.029081 0.052779 -0.463561 0 -0 0</pose>
        <mass>196.901</mass>
        <inertia>
          <ixx>35.0205</ixx>
          <ixy>0.234296</ixy>
          <ixz>-2.0626</ixz>
          <iyy>35.3158</iyy>
          <iyz>-3.7435</iyz>
          <izz>67.7652</izz>
        </inertia>
      </inertial>
      <collision name='blade_collision'>
        <pose frame=''>0 0 0 0 -0 0</pose>
        <geometry>
          <mesh>
            <scale>1 1 1</scale>
            <uri>model://wind_motor/meshes/blade.STL</uri>
          </mesh>
        </geometry>
      </collision>
      <visual name='blade_visual'>
        <pose frame=''>0 0 0 0 -0 0</pose>
        <geometry>
          <mesh>
            <scale>1 1 1</scale>
            <uri>model://wind_motor/meshes/blade.STL</uri>
          </mesh>
        </geometry>
      </visual>
    </link>
    <joint name='motor_blade_joint' type='revolute'>
      <child>blade</child>
      <parent>motor</parent>
      <axis>
        <xyz>0.062217 0.11292 -0.99165</xyz>
        <limit>
          <lower>-1e+16</lower>
          <upper>1e+16</upper>
        </limit>
        <dynamics>
          <spring_reference>0</spring_reference>
          <spring_stiffness>0</spring_stiffness>
        </dynamics>
        <use_parent_model_frame>0</use_parent_model_frame>
      </axis>
    </joint>
    <static>0</static>
    <plugin name='gazebo_ros_control' filename='libgazebo_ros_control.so'>
      <robotNamespace>/wind_motor</robotNamespace>
    </plugin>
  </model>
</sdf>
